2019-02-27T14:50:18|CRITICAL|root|Unhandled exception:Traceback (most recent call last):
  File "C:\ProgramData\Anaconda3\lib\site-packages\ScopeFoundry\hardware.py", line 160, in <lambda>
    op_button.clicked.connect(lambda checked, f=op_func: f())
  File "E:\LabPrograms\Python\PI_stage\pi_stage_HW_test.py", line 219, in go_home
    self.gcs.GOH(self.gcs.axes)
  File "C:\ProgramData\Anaconda3\lib\site-packages\pipython-1.3.4.17-py3.6.egg\pipython\gcscommands.py", line 1507, in GOH
    self.__msgs.send(cmdstr)
  File "C:\ProgramData\Anaconda3\lib\site-packages\pipython-1.3.4.17-py3.6.egg\pipython\gcsmessages.py", line 120, in send
    self.__checkerror(senderr=not self.__embederr)
  File "C:\ProgramData\Anaconda3\lib\site-packages\pipython-1.3.4.17-py3.6.egg\pipython\gcsmessages.py", line 278, in __checkerror
    raise exc  # Raising NoneType while only classes or instances are allowed pylint: disable=E0702
pipython.gcserror.GCSError: Unallowable move attempted on unreferenced axis, or move attempted with servo off (5)

2019-02-27T14:51:31|CRITICAL|root|Unhandled exception:Traceback (most recent call last):
  File "C:\ProgramData\Anaconda3\lib\site-packages\ScopeFoundry\hardware.py", line 208, in enable_connection
    raise err
  File "C:\ProgramData\Anaconda3\lib\site-packages\ScopeFoundry\hardware.py", line 204, in enable_connection
    self.connect()
  File "E:\LabPrograms\Python\PI_stage\pi_stage_HW_test.py", line 87, in connect
    pitools.startup(self.gcs, stages=S.stage.val, refmode=S.ref_mode.val)
  File "C:\ProgramData\Anaconda3\lib\site-packages\pipython-1.3.4.17-py3.6.egg\pipython\pitools.py", line 87, in startup
    waitontarget(pidevice, axes=referencedaxes)
  File "C:\ProgramData\Anaconda3\lib\site-packages\pipython-1.3.4.17-py3.6.egg\pipython\pitools.py", line 178, in waitontarget
    waitonready(pidevice, timeout, predelay)
  File "C:\ProgramData\Anaconda3\lib\site-packages\pipython-1.3.4.17-py3.6.egg\pipython\pitools.py", line 162, in waitonready
    raise SystemError('waitonready() timed out after %.1f seconds' % timeout)
SystemError: waitonready() timed out after 60.0 seconds

